---
title: "编译器错误 CS0156 |Microsoft 文档"
ms.date: 2015-07-20
ms.prod: .net
ms.technology:
- devlang-csharp
ms.topic: article
f1_keywords:
- CS0156
dev_langs:
- CSharp
helpviewer_keywords:
- CS0156
ms.assetid: 32026b1b-bcd7-4464-b63f-3b38c00452a6
caps.latest.revision: 9
author: BillWagner
ms.author: wiwagn
translation.priority.ht:
- de-de
- es-es
- fr-fr
- it-it
- ja-jp
- ko-kr
- ru-ru
- zh-cn
- zh-tw
translation.priority.mt:
- cs-cz
- pl-pl
- pt-br
- tr-tr
translationtype: Machine Translation
ms.sourcegitcommit: a06bd2a17f1d6c7308fa6337c866c1ca2e7281c0
ms.openlocfilehash: 2d8cdfbea9e023dde6326791fb7f8c91725c42b7
ms.lasthandoff: 03/13/2017

---
# <a name="compiler-error-cs0156"></a>编译器错误 CS0156
在嵌套在最近的封闭 catch 子句内部的 finally 子句内不允许使用不带参数的 throw 语句  
  
 一个[引发](../../csharp/language-reference/keywords/throw.md)不带参数的语句只能出现在**捕获**不带任何参数的子句。  
  
 有关详细信息，请参阅[异常处理语句](../../csharp/language-reference/keywords/exception-handling-statements.md)和[异常和异常处理](../../csharp/programming-guide/exceptions/index.md)。  
  
 下面的示例生成 CS0156：  
  
```  
// CS0156.cs  
using System;  
  
namespace MyNamespace  
{  
   public class MyClass2 : Exception  
   {  
   }  
  
   public class MyClass  
   {  
      public static void Main()  
      {  
         try  
         {  
            throw;   // CS0156  
         }  
  
         catch(MyClass2)  
         {  
            throw;   // this throw is valid  
         }  
      }  
   }  
}  
```
